Workbook

Sheet Summary
B1: ORBITAL DATA COMPUTE — INTEGRATED MODEL
B2: Self-initiated work sample · J. Shapiro · inputs tagged [FACT]/[EST]/[REVEAL]/[TGT]/[SPX-IN] · shared inputs on the Global Assumptions tab
B4: ANALYSIS 1 — Orbital vs. Terrestrial unit economics (1 GW)
B5: Orbital build cost | C5: ='A1 Orbital'!C26 -> 81.39726
B6: Terrestrial build cost | C6: ='A1 Terrestrial'!C19 -> 38
B7: Orbital premium — per watt | C7: ='A1 Orbital'!C26/'A1 Terrestrial'!C19 -> 2.1420332
B8: Cost per effective PFLOP-hr — inference | C8: ='A1 EffCompute'!E15 -> 2.1623587
B9: Cost per effective PFLOP-hr — training | C9: ='A1 EffCompute'!D15 -> 4.8653071 | E9: networking tax
B11: ANALYSIS 2 — Bastrop insource vs. outsource
B12: Net NPV of insourcing (7 yr) | C12: ='A2 BuildVsBuy'!C22 -> 933946.48 | E12: illustrative inputs
B13: Mature in-house unit cost | C13: ='A2 BuildVsBuy'!C23 -> 1.9646292
B15: ANALYSIS 3 — AI-Sat production ramp
B16: Cumulative power to orbit (final yr) | C16: ='A3 Ramp'!C25 -> 1.158176
B17: Cumulative capex (final yr) | C17: ='A3 Ramp'!C26 -> 23538.203
B18: Cost per satellite (final yr) | C18: ='A3 Ramp'!C27 -> 0.59944211 | E18: 85% learning curve
B20: RADIATOR THERMAL TAX
B21: Implied radiator temperature | C21: ='RAD Model'!C14 -> 347.14975
B22: Margin to silicon throttle | C22: ='RAD Model'!C15 -> 10.850254 | E22: headroom
B23: Radiator mass (1 GW) | C23: ='A1 Orbital'!C13/1000 -> 5000
B25: HEADLINE: orbital AI compute is ~2x terrestrial for inference and ~5x for training — a launch-cost option and an inference play, not general compute. The split is set by interconnect bandwidth (1 Tbps laser vs ~1,040 Tbps NVLink), not dollars.

Sheet Global Assumptions
B1: GLOBAL ASSUMPTIONS — single source of truth
B2: Shared inputs live here only. Each analysis links to these cells (green font), so changing a value here updates every model — no drift.
B3: Parameter | C3: Value | D3: Unit | E3: Tag | F3: Used by
B5: FINANCIAL
B6: Discount rate (WACC) | C6: 0.12 | D6: %/yr | E6: [SPX-IN] | F6: A1, A2
B7: Launch cost to LEO | C7: 1000 | D7: $/kg | E7: [TGT] | F7: A1, A3, Radiator
B8: Target cluster power | C8: 1000 | D8: MW | E8: [EST] | F8: A1, Radiator
B10: AI1 REFERENCE SPECS (June 8 2026 reveal / S-1)
B11: Compute payload (avg) | C11: 120 | D11: kW/sat | E11: [REVEAL] | F11: A3
B12: Specific power | C12: 70 | D12: kW/ton | E12: [REVEAL] | F12: A3
B13: Radiator flux (double-sided) | C13: 1400 | D13: W/m2 | E13: [REVEAL] | F13: A1, Radiator
B15: NOTE: A1 cost model uses a CONSERVATIVE 36.5 W/kg specific-power base (not the AI1 70 kW/ton above) and stresses 70 as the bull case — deliberate; see A1 Inputs C12.

Sheet A1 Inputs
B2: INPUTS & ASSUMPTIONS
B3: Blue = input you can change · Yellow = most needs a real SpaceX number · tags: [FACT]/[EST]/[REVEAL]/[TGT]/[SPX-IN]
B4: SCOPE NOTE: both builds are ALL-IN (include power generation).
B5: TARGET SYSTEM
B6: Target cluster power (deployed compute) | C6: ='Global Assumptions'!$C$8 -> 1000 | D6: MW | E6: [EST] | F6: Sized to 1 GW to match published comparison models (McCalip, Epoch AI)
B7: Analysis period | C7: 10 | D7: years | E7: [EST] | F7: Standard infra horizon
B8: Discount rate (WACC) | C8: ='Global Assumptions'!$C$6 -> 0.12 | D8: %/yr | E8: [SPX-IN] | F8: Placeholder; use SpaceX cost of capital
B10: LAUNCH ECONOMICS (the master variable)
B11: Launch cost to LEO | C11: ='Global Assumptions'!$C$7 -> 1000 | D11: $/kg | E11: [TGT] | F11: Starship TARGET; not yet demonstrated. Falcon 9 rideshare = $7,000/kg (Feb 2026). McCalip baseline $1,000/kg.
B12: System specific power | C12: 36.5 | D12: W/kg | E12: [EST] | F12: BASE CASE conservative 36.5 W/kg = power+bus+structure EXCLUDING compute-rejection radiators (McCalip heritage basis). Radiators are added separately on tab 2 to CORRECT that omission — no overlap. AI1 reveal claims 70 kW/ton [REVEAL] = bull upside; stressed in tab 5.
B14: SPACE HARDWARE & POWER
B15: Compute accelerator cost | C15: =25*1.4 -> 35 | D15: $/W | E15: [EST] | F15: GB300-class ~$25/W on a hardware-COST basis (not Nvidia retail ~$54/W, which embeds vendor margin SpaceX insources around) x 1.4 space-grade premium.
B16: Power system (solar+PMAD) | C16: 8 | D16: $/W | E16: [EST] | F16: Space solar array + power mgmt/distribution per watt; order-of-magnitude
B17: Bus, structure, integration | C17: 6 | D17: $/W | E17: [EST] | F17: Satellite bus, structure, harness, assembly/test per watt
B19: Compute + bus hardware cost (built up) | C19: =SUM(C15:C17) -> 49 | D19: $/W | E19: [EST] | F19: Independent build-up (compute + power + bus). Ratio to terrestrial falls out; NOT calibrated to a target.
B20: Solar cell degradation | C20: 0.025
B21: GPU annual failure rate | C21: 0.09 | D21: %/yr | E21: [EST] | F21: Meta Llama-3 fleet figure (9%/yr) [EST]; no on-orbit repair. Space radiation may push this higher — which only strengthens the case (more re-launch).
B22: Orbital ops & ground network | C22: 0.01 | D22: %capex/yr | E22: [SPX-IN] | F22: Illustrative annual O&M as % of hardware capex
B24: THERMAL (radiative cooling only — vacuum)
B25: Radiator heat rejection | C25: ='Global Assumptions'!$C$13 -> 1400 | D25: W/m2 | E25: [REVEAL] | F25: AI1 reveal: double-sided radiators 1,400 W/m2
B26: Radiator areal mass | C26: 7 | D26: kg/m2 | E26: [EST] | F26: ISS ~2.7 kg/m2; modern deployable 5-10 kg/m2; midpoint 7
B28: TERRESTRIAL BENCHMARK
B29: All-in build capex | C29: 38000 | D29: $/kW | E29: [EST] | F29: Epoch AI 1 GW ALL-IN incl on-site power generation = $38/W. (McCalip infra-only = ~$15/W; we use all-in to match orbital scope, which includes its own solar power.)
B30: IT (GPU) refresh life | C30: 5 | D30: years | E30: [EST] | F30: Epoch AI base case
B31: Facility / shell life | C31: 14 | D31: years | E31: [EST] | F31: Epoch AI base case
B32: IT share of capex | C32: 0.6 | D32: % | E32: [EST] | F32: Epoch AI: servers ~60% of cost
B33: Electricity price | C33: 0.0834
B34: PUE (power usage effectiveness) | C34: 1.15 | D34: x | E34: [EST] | F34: Modern AI DC ~1.1-1.2
B35: Non-power opex | C35: 0.02 | D35: %capex/yr | E35: [EST] | F35: Maintenance/staff/network
B37: EFFECTIVE COMPUTE (utilization)
B38: Accelerator compute density | C38: 1.45 | D38: PFLOP/kW | E38: [FACT] | F38: ~H100 FP16-dense reference (989 TFLOP / 700W ~ 1.4 PFLOP/kW). FP8 dense is ~1,979 TFLOP; figure cancels in the orbital/terrestrial ratio, used only for the effective-PFLOP denominator.
B39: MFU — terrestrial training | C39: 0.45 | D39: % | E39: [FACT] | F39: PaLM 46%, Llama-3 38-43%, MegaScale 55%
B40: MFU — orbital training | C40: 0.2 | D40: % | E40: [SPX-IN] | F40: Lower: ISL bandwidth ~1 Tbps vs ~1,040 Tbps intra-rack NVLink
B41: MFU — orbital inference | C41: 0.45 | D41: % | E41: [SPX-IN] | F41: Comparable to terrestrial for batch inference w/ preloaded weights
B44: J. Shapiro · Prepared as an independent work sample · all figures public-sourced or labeled illustrative

Sheet A1 Orbital
B2: ORBITAL CLUSTER — BOTTOMS-UP $/W
B4: Target power | C4: ='A1 Inputs'!$C$6*1000 -> 1000000 | D4: kW | F4: MW -> kW
B5: System mass to orbit | C5: =C4*1000/'A1 Inputs'!$C$12 -> 27397260 | D5: kg | F5: power / specific power
B6: Mass to orbit, incl. radiator (t) | C6: =(C5+C13)/1000 -> 32397.26 | D6: t
B7: Starship launches @150t (incl. radiator) | C7: =(C5+C13)/1000/150 -> 215.98174 | D7: launches
B9: Launch cost | C9: =C5*'A1 Inputs'!$C$11 -> 2.739726e+10 | D9: $ | F9: mass x $/kg
B10: Compute + bus hardware | C10: =C4*1000*'A1 Inputs'!$C$19 -> 49000000000 | D10: $ | F10: W x $/W
B11: Heat to reject (~= compute power) | C11: =C4 -> 1000000 | D11: kW | F11: assume ~100% of electrical power -> heat
B12: Radiator area | C12: =C11*1000/'A1 Inputs'!$C$25 -> 714285.71 | D12: m2 | F12: heat W / (W/m2)
B13: Radiator mass | C13: =C12*'A1 Inputs'!$C$26 -> 5000000 | D13: kg
B14: Radiator launch cost (incremental) | C14: =C13*'A1 Inputs'!$C$11 -> 5000000000 | D14: $ | F14: thermal mass tax McCalip omits
B16: Total upfront capex | C16: =C9+C10+C14 -> 8.139726e+10 | D16: $
B18: Capital recovery factor | C18: ='A1 Inputs'!$C$8*(1+'A1 Inputs'!$C$8)^'A1 Inputs'!$C$7/((1+'A1 Inputs'!$C$8)^'A1 Inputs'!$C$7-1) -> 0.17698416 | D18: x | F18: CRF over analysis period
B19: Annualized capex | C19: =C16*C18 -> 1.4406026e+10 | D19: $/yr
B20: GPU failure replacement | C20: =C10*'A1 Inputs'!$C$21 -> 4410000000 | D20: $/yr | F20: no repair; amortized replacement
B21: GPU replacement launch cost | C21: =C5*'A1 Inputs'!$C$21*'A1 Inputs'!$C$11 -> 2.4657534e+09 | D21: $/yr | F21: No on-orbit repair: replacement GPUs must be re-launched. Mass x failure rate x launch $/kg. Worsens orbital case (correct direction).
B22: Ops & ground network | C22: =C16*'A1 Inputs'!$C$22 -> 8.139726e+08 | D22: $/yr
B24: Total annual cost | C24: =C19+C20+C21+C22 -> 2.2095752e+10 | D24: $/yr
B26: Cost per watt (upfront capex) | C26: =C16/(C4*1000) -> 81.39726 | D26: $/W
B27: Solar availability derate (avg over life) | C27: =(1+(1-'A1 Inputs'!$C$20)^'A1 Inputs'!$C$7)/2 -> 0.88816481 | D27: x | F27: Average solar power availability over life given degradation; derates delivered MW.
B28: Cost per MW-year (annualized) | C28: =C24/('A1 Inputs'!$C$6*C27) -> 24877986 | D28: $/MW-yr
B31: J. Shapiro · Prepared as an independent work sample · all figures public-sourced or labeled illustrative

Sheet A1 Terrestrial
B2: TERRESTRIAL AI DATA CENTER — BOTTOMS-UP $/W
B4: Target power | C4: ='A1 Inputs'!$C$6*1000 -> 1000000 | D4: kW
B5: Total build capex | C5: =C4*'A1 Inputs'!$C$29 -> 38000000000 | D5: $ | F5: kW x $/kW
B6: of which IT (GPU) capex | C6: =C5*'A1 Inputs'!$C$32 -> 22800000000 | D6: $
B7: of which facility capex | C7: =C5-C6 -> 15200000000 | D7: $
B9: CRF — IT (refresh life) | C9: ='A1 Inputs'!$C$8*(1+'A1 Inputs'!$C$8)^'A1 Inputs'!$C$30/((1+'A1 Inputs'!$C$8)^'A1 Inputs'!$C$30-1) -> 0.27740973 | D9: x
B10: CRF — facility life | C10: ='A1 Inputs'!$C$8*(1+'A1 Inputs'!$C$8)^'A1 Inputs'!$C$31/((1+'A1 Inputs'!$C$8)^'A1 Inputs'!$C$31-1) -> 0.15087125 | D10: x
B11: Annualized IT capex | C11: =C6*C9 -> 6.3249419e+09 | D11: $/yr
B12: Annualized facility capex | C12: =C7*C10 -> 2.2932429e+09 | D12: $/yr
B14: Annual electricity (incl PUE) | C14: =C4*'A1 Inputs'!$C$34*8760*'A1 Inputs'!$C$33 -> 840171600 | D14: $/yr | F14: kW x PUE x hrs x $/kWh
B15: Non-power opex | C15: =C5*'A1 Inputs'!$C$35 -> 760000000 | D15: $/yr
B17: Total annual cost | C17: =C11+C12+C14+C15 -> 1.0218356e+10 | D17: $/yr
B19: Cost per watt (upfront capex) | C19: =C5/(C4*1000) -> 38 | D19: $/W
B20: Cost per MW-year (annualized) | C20: =C17/'A1 Inputs'!$C$6 -> 10218356 | D20: $/MW-yr
B23: J. Shapiro · Prepared as an independent work sample · all figures public-sourced or labeled illustrative

Sheet A1 EffCompute
B2: COST PER EFFECTIVE PFLOP-HOUR (apples-to-apples)
B3: Peak FLOPS is misleading; only the MODEL FLOPS UTILIZATION fraction is usable. Networking sets the ceiling.
C5: Terrestrial | D5: Orbital (train) | E5: Orbital (infer)
B6: Annual system cost ($/yr) | C6: ='A1 Terrestrial'!C17 -> 1.0218356e+10 | D6: ='A1 Orbital'!C24 -> 2.2095752e+10 | E6: ='A1 Orbital'!C24 -> 2.2095752e+10 | G6: from build tabs
B7: Deployed power (MW) | C7: ='A1 Inputs'!$C$6 -> 1000 | D7: ='A1 Inputs'!$C$6 -> 1000 | E7: ='A1 Inputs'!$C$6 -> 1000 | G7: nameplate
B8: Peak compute (PFLOP) | C8: =C7*1000*'A1 Inputs'!$C$38 -> 1450000 | D8: =D7*1000*'A1 Inputs'!$C$38 -> 1450000 | E8: =E7*1000*'A1 Inputs'!$C$38 -> 1450000 | G8: MW x 1000 x PFLOP/kW
B9: MFU (usable fraction) | C9: ='A1 Inputs'!$C$39 -> 0.45 | D9: ='A1 Inputs'!$C$40 -> 0.2 | E9: ='A1 Inputs'!$C$41 -> 0.45 | G9: utilization haircut
B10: Effective compute (PFLOP) | C10: =C8*C9 -> 652500 | D10: =D8*D9 -> 290000 | E10: =E8*E9 -> 652500
B11: Effective PFLOP-hours / yr | C11: =C10*8760 -> 5715900000 | D11: =D10*8760 -> 2540400000 | E11: =E10*8760 -> 5715900000
B13: COST PER EFFECTIVE PFLOP-HOUR | C13: =C6/C11 -> 1.7877073 | D13: =D6/D11 -> 8.6977453 | E13: =E6/E11 -> 3.8656646
B15: Orbital premium vs terrestrial | C15: ="--" -> -- | D15: =D13/C13 -> 4.8653071 | E15: =E13/C13 -> 2.1623587
B18: THE NETWORKING TAX (why inference, not training)
B19: Intra-rack NVLink-5 fabric (GB300 NVL72): ~130 TB/s aggregate = ~1,040 Tbps [FACT, NVIDIA]
B20: AI1 inter-satellite laser link: ~1 Tbps [REVEAL, Jun 8 2026] -> ~1,000x below intra-rack bandwidth
B21: Even Google Suncatcher's 10 Tbps DWDM target ~ a single GPU's NVLink budget (14.4 Tbps).
B22: Consequence: tensor-parallel TRAINING needs NVLink-class bandwidth orbit cannot supply -> low orbital-train MFU.
B23: Batch INFERENCE with preloaded weights is embarrassingly parallel -> orbital MFU ~ terrestrial. This is the
B24: workload SpaceX's S-1 names ('energy-intensive AI workloads, such as inference demand').
B27: J. Shapiro · Prepared as an independent work sample · all figures public-sourced or labeled illustrative

Sheet A1 Sensitivity
B2: CROSSOVER ANALYSIS — Orbital $/W ÷ Terrestrial $/W
B3: Values < 1.0x (green) = orbital cheaper. The model recomputes orbital $/W for each launch-cost / specific-power pair.
B5: Terrestrial $/W (constant): | D5: ='A1 Terrestrial'!C19 -> 38
B7: Launch $/kg \ Specific power (W/kg) -> | C7: 50 | D7: 70 | E7: 100 | F7: 150 | G7: 250 | H7: 400 | I7: 700
B8: 100 | C8: =(100/50 + 'A1 Inputs'!$C$19 + ('A1 Inputs'!$C$26/'A1 Inputs'!$C$25)*100) / $D$5 -> 1.3552632 | D8: =(100/70 + 'A1 Inputs'!$C$19 + ('A1 Inputs'!$C$26/'A1 Inputs'!$C$25)*100) / $D$5 -> 1.3402256 | E8: =(100/100 + 'A1 Inputs'!$C$19 + ('A1 Inputs'!$C$26/'A1 Inputs'!$C$25)*100) / $D$5 -> 1.3289474 | F8: =(100/150 + 'A1 Inputs'!$C$19 + ('A1 Inputs'!$C$26/'A1 Inputs'!$C$25)*100) / $D$5 -> 1.3201754 | G8: =(100/250 + 'A1 Inputs'!$C$19 + ('A1 Inputs'!$C$26/'A1 Inputs'!$C$25)*100) / $D$5 -> 1.3131579 | H8: =(100/400 + 'A1 Inputs'!$C$19 + ('A1 Inputs'!$C$26/'A1 Inputs'!$C$25)*100) / $D$5 -> 1.3092105 | I8: =(100/700 + 'A1 Inputs'!$C$19 + ('A1 Inputs'!$C$26/'A1 Inputs'!$C$25)*100) / $D$5 -> 1.306391
B9: 200 | C9: =(200/50 + 'A1 Inputs'!$C$19 + ('A1 Inputs'!$C$26/'A1 Inputs'!$C$25)*200) / $D$5 -> 1.4210526 | D9: =(200/70 + 'A1 Inputs'!$C$19 + ('A1 Inputs'!$C$26/'A1 Inputs'!$C$25)*200) / $D$5 -> 1.3909774 | E9: =(200/100 + 'A1 Inputs'!$C$19 + ('A1 Inputs'!$C$26/'A1 Inputs'!$C$25)*200) / $D$5 -> 1.3684211 | F9: =(200/150 + 'A1 Inputs'!$C$19 + ('A1 Inputs'!$C$26/'A1 Inputs'!$C$25)*200) / $D$5 -> 1.3508772 | G9: =(200/250 + 'A1 Inputs'!$C$19 + ('A1 Inputs'!$C$26/'A1 Inputs'!$C$25)*200) / $D$5 -> 1.3368421 | H9: =(200/400 + 'A1 Inputs'!$C$19 + ('A1 Inputs'!$C$26/'A1 Inputs'!$C$25)*200) / $D$5 -> 1.3289474 | I9: =(200/700 + 'A1 Inputs'!$C$19 + ('A1 Inputs'!$C$26/'A1 Inputs'!$C$25)*200) / $D$5 -> 1.3233083
B10: 300 | C10: =(300/50 + 'A1 Inputs'!$C$19 + ('A1 Inputs'!$C$26/'A1 Inputs'!$C$25)*300) / $D$5 -> 1.4868421 | D10: =(300/70 + 'A1 Inputs'!$C$19 + ('A1 Inputs'!$C$26/'A1 Inputs'!$C$25)*300) / $D$5 -> 1.4417293 | E10: =(300/100 + 'A1 Inputs'!$C$19 + ('A1 Inputs'!$C$26/'A1 Inputs'!$C$25)*300) / $D$5 -> 1.4078947 | F10: =(300/150 + 'A1 Inputs'!$C$19 + ('A1 Inputs'!$C$26/'A1 Inputs'!$C$25)*300) / $D$5 -> 1.3815789 | G10: =(300/250 + 'A1 Inputs'!$C$19 + ('A1 Inputs'!$C$26/'A1 Inputs'!$C$25)*300) / $D$5 -> 1.3605263 | H10: =(300/400 + 'A1 Inputs'!$C$19 + ('A1 Inputs'!$C$26/'A1 Inputs'!$C$25)*300) / $D$5 -> 1.3486842 | I10: =(300/700 + 'A1 Inputs'!$C$19 + ('A1 Inputs'!$C$26/'A1 Inputs'!$C$25)*300) / $D$5 -> 1.3402256
B11: 500 | C11: =(500/50 + 'A1 Inputs'!$C$19 + ('A1 Inputs'!$C$26/'A1 Inputs'!$C$25)*500) / $D$5 -> 1.6184211 | D11: =(500/70 + 'A1 Inputs'!$C$19 + ('A1 Inputs'!$C$26/'A1 Inputs'!$C$25)*500) / $D$5 -> 1.5432331 | E11: =(500/100 + 'A1 Inputs'!$C$19 + ('A1 Inputs'!$C$26/'A1 Inputs'!$C$25)*500) / $D$5 -> 1.4868421 | F11: =(500/150 + 'A1 Inputs'!$C$19 + ('A1 Inputs'!$C$26/'A1 Inputs'!$C$25)*500) / $D$5 -> 1.4429825 | G11: =(500/250 + 'A1 Inputs'!$C$19 + ('A1 Inputs'!$C$26/'A1 Inputs'!$C$25)*500) / $D$5 -> 1.4078947 | H11: =(500/400 + 'A1 Inputs'!$C$19 + ('A1 Inputs'!$C$26/'A1 Inputs'!$C$25)*500) / $D$5 -> 1.3881579 | I11: =(500/700 + 'A1 Inputs'!$C$19 + ('A1 Inputs'!$C$26/'A1 Inputs'!$C$25)*500) / $D$5 -> 1.3740602
B12: 1000 | C12: =(1000/50 + 'A1 Inputs'!$C$19 + ('A1 Inputs'!$C$26/'A1 Inputs'!$C$25)*1000) / $D$5 -> 1.9473684 | D12: =(1000/70 + 'A1 Inputs'!$C$19 + ('A1 Inputs'!$C$26/'A1 Inputs'!$C$25)*1000) / $D$5 -> 1.7969925 | E12: =(1000/100 + 'A1 Inputs'!$C$19 + ('A1 Inputs'!$C$26/'A1 Inputs'!$C$25)*1000) / $D$5 -> 1.6842105 | F12: =(1000/150 + 'A1 Inputs'!$C$19 + ('A1 Inputs'!$C$26/'A1 Inputs'!$C$25)*1000) / $D$5 -> 1.5964912 | G12: =(1000/250 + 'A1 Inputs'!$C$19 + ('A1 Inputs'!$C$26/'A1 Inputs'!$C$25)*1000) / $D$5 -> 1.5263158 | H12: =(1000/400 + 'A1 Inputs'!$C$19 + ('A1 Inputs'!$C$26/'A1 Inputs'!$C$25)*1000) / $D$5 -> 1.4868421 | I12: =(1000/700 + 'A1 Inputs'!$C$19 + ('A1 Inputs'!$C$26/'A1 Inputs'!$C$25)*1000) / $D$5 -> 1.4586466
B13: 2000 | C13: =(2000/50 + 'A1 Inputs'!$C$19 + ('A1 Inputs'!$C$26/'A1 Inputs'!$C$25)*2000) / $D$5 -> 2.6052632 | D13: =(2000/70 + 'A1 Inputs'!$C$19 + ('A1 Inputs'!$C$26/'A1 Inputs'!$C$25)*2000) / $D$5 -> 2.3045113 | E13: =(2000/100 + 'A1 Inputs'!$C$19 + ('A1 Inputs'!$C$26/'A1 Inputs'!$C$25)*2000) / $D$5 -> 2.0789474 | F13: =(2000/150 + 'A1 Inputs'!$C$19 + ('A1 Inputs'!$C$26/'A1 Inputs'!$C$25)*2000) / $D$5 -> 1.9035088 | G13: =(2000/250 + 'A1 Inputs'!$C$19 + ('A1 Inputs'!$C$26/'A1 Inputs'!$C$25)*2000) / $D$5 -> 1.7631579 | H13: =(2000/400 + 'A1 Inputs'!$C$19 + ('A1 Inputs'!$C$26/'A1 Inputs'!$C$25)*2000) / $D$5 -> 1.6842105 | I13: =(2000/700 + 'A1 Inputs'!$C$19 + ('A1 Inputs'!$C$26/'A1 Inputs'!$C$25)*2000) / $D$5 -> 1.6278195
B14: 5000 | C14: =(5000/50 + 'A1 Inputs'!$C$19 + ('A1 Inputs'!$C$26/'A1 Inputs'!$C$25)*5000) / $D$5 -> 4.5789474 | D14: =(5000/70 + 'A1 Inputs'!$C$19 + ('A1 Inputs'!$C$26/'A1 Inputs'!$C$25)*5000) / $D$5 -> 3.8270677 | E14: =(5000/100 + 'A1 Inputs'!$C$19 + ('A1 Inputs'!$C$26/'A1 Inputs'!$C$25)*5000) / $D$5 -> 3.2631579 | F14: =(5000/150 + 'A1 Inputs'!$C$19 + ('A1 Inputs'!$C$26/'A1 Inputs'!$C$25)*5000) / $D$5 -> 2.8245614 | G14: =(5000/250 + 'A1 Inputs'!$C$19 + ('A1 Inputs'!$C$26/'A1 Inputs'!$C$25)*5000) / $D$5 -> 2.4736842 | H14: =(5000/400 + 'A1 Inputs'!$C$19 + ('A1 Inputs'!$C$26/'A1 Inputs'!$C$25)*5000) / $D$5 -> 2.2763158 | I14: =(5000/700 + 'A1 Inputs'!$C$19 + ('A1 Inputs'!$C$26/'A1 Inputs'!$C$25)*5000) / $D$5 -> 2.1353383
B15: 7000 | C15: =(7000/50 + 'A1 Inputs'!$C$19 + ('A1 Inputs'!$C$26/'A1 Inputs'!$C$25)*7000) / $D$5 -> 5.8947368 | D15: =(7000/70 + 'A1 Inputs'!$C$19 + ('A1 Inputs'!$C$26/'A1 Inputs'!$C$25)*7000) / $D$5 -> 4.8421053 | E15: =(7000/100 + 'A1 Inputs'!$C$19 + ('A1 Inputs'!$C$26/'A1 Inputs'!$C$25)*7000) / $D$5 -> 4.0526316 | F15: =(7000/150 + 'A1 Inputs'!$C$19 + ('A1 Inputs'!$C$26/'A1 Inputs'!$C$25)*7000) / $D$5 -> 3.4385965 | G15: =(7000/250 + 'A1 Inputs'!$C$19 + ('A1 Inputs'!$C$26/'A1 Inputs'!$C$25)*7000) / $D$5 -> 2.9473684 | H15: =(7000/400 + 'A1 Inputs'!$C$19 + ('A1 Inputs'!$C$26/'A1 Inputs'!$C$25)*7000) / $D$5 -> 2.6710526 | I15: =(7000/700 + 'A1 Inputs'!$C$19 + ('A1 Inputs'!$C$26/'A1 Inputs'!$C$25)*7000) / $D$5 -> 2.4736842
B17: READING THIS TABLE:
B18: Each cell = orbital cost per watt / terrestrial cost per watt, recomputed at that launch cost (row) and specific power (col).
B19: Holds hardware $/W, radiator mass, and radiator W/m2 at their Inputs-tab values; change those to re-stress.
B20: GREEN (<1.0x) = orbital cheaper per watt. YELLOW (1-2x) = contested. RED (>2x) = terrestrial wins clearly.
B22: TAKEAWAY: orbital reaches parity per-watt only in the bottom-left corner — LOW launch cost AND HIGH specific power
B23: together. At the demonstrated Falcon-9 rate ($7,000/kg) nothing is close. This is a launch-cost option, not a today trade.
B24: Note: this is capex-per-watt; the asset-life and MFU levers (tabs 2-4) further favor terrestrial for training workloads.
B25: NOTE (specific power >= 70 W/kg): AI1s 70 kW/ton is likely an ALL-IN figure already including radiators, so the radiator term added here may double-count in those columns — read them as a CONSERVATIVE upper bound.
B26: NOTE (base case): the 36.5 W/kg base sits just left of the 50 W/kg column (~1.95-2.0x here). This grid is the simplified capex-per-watt ratio; the headline 2.14x is the full TCO / effective-PFLOP figure on tabs 2-4.
B30: CROSSOVER #2 — Orbital ÷ Terrestrial cost per MW-YEAR (annualized), by launch $/kg × asset life
B31: Asset life drives the capital-recovery factor AND the solar-degradation derate; this isolates that lever on a full annualized basis (incl. compute, radiator, GPU re-launch). Terrestrial denominator uses its own 5/14-yr lives.
B32: Terrestrial $/MW-yr (constant): | C32: ='A1 Terrestrial'!C20 -> 10218356
B33: Launch $/kg \ Asset life (yrs) -> | C33: 3 | D33: 5 | E33: 7 | F33: 10 | G33: 14 | H33: 20
B34: 100 | C34: =((('A1 Orbital'!$C$5*$B34+'A1 Orbital'!$C$10+'A1 Orbital'!$C$13*$B34)*('A1 Inputs'!$C$8*(1+'A1 Inputs'!$C$8)^C$33/((1+'A1 Inputs'!$C$8)^C$33-1))+'A1 Orbital'!$C$20+'A1 Orbital'!$C$5*'A1 Inputs'!$C$21*$B34+('A1 Orbital'!$C$5*$B34+'A1 Orbital'!$C$10+'A1 Orbital'!$C$13*$B34)*'A1 Inputs'!$C$22)/('A1 Inputs'!$C$6*((1+(1-'A1 Inputs'!$C$20)^C$33)/2)))/'A1 Terrestrial'!$C$20 -> 2.7353822 | D34: =((('A1 Orbital'!$C$5*$B34+'A1 Orbital'!$C$10+'A1 Orbital'!$C$13*$B34)*('A1 Inputs'!$C$8*(1+'A1 Inputs'!$C$8)^D$33/((1+'A1 Inputs'!$C$8)^D$33-1))+'A1 Orbital'!$C$20+'A1 Orbital'!$C$5*'A1 Inputs'!$C$21*$B34+('A1 Orbital'!$C$5*$B34+'A1 Orbital'!$C$10+'A1 Orbital'!$C$13*$B34)*'A1 Inputs'!$C$22)/('A1 Inputs'!$C$6*((1+(1-'A1 Inputs'!$C$20)^D$33)/2)))/'A1 Terrestrial'!$C$20 -> 2.0467258 | E34: =((('A1 Orbital'!$C$5*$B34+'A1 Orbital'!$C$10+'A1 Orbital'!$C$13*$B34)*('A1 Inputs'!$C$8*(1+'A1 Inputs'!$C$8)^E$33/((1+'A1 Inputs'!$C$8)^E$33-1))+'A1 Orbital'!$C$20+'A1 Orbital'!$C$5*'A1 Inputs'!$C$21*$B34+('A1 Orbital'!$C$5*$B34+'A1 Orbital'!$C$10+'A1 Orbital'!$C$13*$B34)*'A1 Inputs'!$C$22)/('A1 Inputs'!$C$6*((1+(1-'A1 Inputs'!$C$20)^E$33)/2)))/'A1 Terrestrial'!$C$20 -> 1.7708341 | F34: =((('A1 Orbital'!$C$5*$B34+'A1 Orbital'!$C$10+'A1 Orbital'!$C$13*$B34)*('A1 Inputs'!$C$8*(1+'A1 Inputs'!$C$8)^F$33/((1+'A1 Inputs'!$C$8)^F$33-1))+'A1 Orbital'!$C$20+'A1 Orbital'!$C$5*'A1 Inputs'!$C$21*$B34+('A1 Orbital'!$C$5*$B34+'A1 Orbital'!$C$10+'A1 Orbital'!$C$13*$B34)*'A1 Inputs'!$C$22)/('A1 Inputs'!$C$6*((1+(1-'A1 Inputs'!$C$20)^F$33)/2)))/'A1 Terrestrial'!$C$20 -> 1.5893827 | G34: =((('A1 Orbital'!$C$5*$B34+'A1 Orbital'!$C$10+'A1 Orbital'!$C$13*$B34)*('A1 Inputs'!$C$8*(1+'A1 Inputs'!$C$8)^G$33/((1+'A1 Inputs'!$C$8)^G$33-1))+'A1 Orbital'!$C$20+'A1 Orbital'!$C$5*'A1 Inputs'!$C$21*$B34+('A1 Orbital'!$C$5*$B34+'A1 Orbital'!$C$10+'A1 Orbital'!$C$13*$B34)*'A1 Inputs'!$C$22)/('A1 Inputs'!$C$6*((1+(1-'A1 Inputs'!$C$20)^G$33)/2)))/'A1 Terrestrial'!$C$20 -> 1.5023106 | H34: =((('A1 Orbital'!$C$5*$B34+'A1 Orbital'!$C$10+'A1 Orbital'!$C$13*$B34)*('A1 Inputs'!$C$8*(1+'A1 Inputs'!$C$8)^H$33/((1+'A1 Inputs'!$C$8)^H$33-1))+'A1 Orbital'!$C$20+'A1 Orbital'!$C$5*'A1 Inputs'!$C$21*$B34+('A1 Orbital'!$C$5*$B34+'A1 Orbital'!$C$10+'A1 Orbital'!$C$13*$B34)*'A1 Inputs'!$C$22)/('A1 Inputs'!$C$6*((1+(1-'A1 Inputs'!$C$20)^H$33)/2)))/'A1 Terrestrial'!$C$20 -> 1.4865832
B35: 200 | C35: =((('A1 Orbital'!$C$5*$B35+'A1 Orbital'!$C$10+'A1 Orbital'!$C$13*$B35)*('A1 Inputs'!$C$8*(1+'A1 Inputs'!$C$8)^C$33/((1+'A1 Inputs'!$C$8)^C$33-1))+'A1 Orbital'!$C$20+'A1 Orbital'!$C$5*'A1 Inputs'!$C$21*$B35+('A1 Orbital'!$C$5*$B35+'A1 Orbital'!$C$10+'A1 Orbital'!$C$13*$B35)*'A1 Inputs'!$C$22)/('A1 Inputs'!$C$6*((1+(1-'A1 Inputs'!$C$20)^C$33)/2)))/'A1 Terrestrial'!$C$20 -> 2.9007335 | D35: =((('A1 Orbital'!$C$5*$B35+'A1 Orbital'!$C$10+'A1 Orbital'!$C$13*$B35)*('A1 Inputs'!$C$8*(1+'A1 Inputs'!$C$8)^D$33/((1+'A1 Inputs'!$C$8)^D$33-1))+'A1 Orbital'!$C$20+'A1 Orbital'!$C$5*'A1 Inputs'!$C$21*$B35+('A1 Orbital'!$C$5*$B35+'A1 Orbital'!$C$10+'A1 Orbital'!$C$13*$B35)*'A1 Inputs'!$C$22)/('A1 Inputs'!$C$6*((1+(1-'A1 Inputs'!$C$20)^D$33)/2)))/'A1 Terrestrial'!$C$20 -> 2.1692648 | E35: =((('A1 Orbital'!$C$5*$B35+'A1 Orbital'!$C$10+'A1 Orbital'!$C$13*$B35)*('A1 Inputs'!$C$8*(1+'A1 Inputs'!$C$8)^E$33/((1+'A1 Inputs'!$C$8)^E$33-1))+'A1 Orbital'!$C$20+'A1 Orbital'!$C$5*'A1 Inputs'!$C$21*$B35+('A1 Orbital'!$C$5*$B35+'A1 Orbital'!$C$10+'A1 Orbital'!$C$13*$B35)*'A1 Inputs'!$C$22)/('A1 Inputs'!$C$6*((1+(1-'A1 Inputs'!$C$20)^E$33)/2)))/'A1 Terrestrial'!$C$20 -> 1.8761593 | F35: =((('A1 Orbital'!$C$5*$B35+'A1 Orbital'!$C$10+'A1 Orbital'!$C$13*$B35)*('A1 Inputs'!$C$8*(1+'A1 Inputs'!$C$8)^F$33/((1+'A1 Inputs'!$C$8)^F$33-1))+'A1 Orbital'!$C$20+'A1 Orbital'!$C$5*'A1 Inputs'!$C$21*$B35+('A1 Orbital'!$C$5*$B35+'A1 Orbital'!$C$10+'A1 Orbital'!$C$13*$B35)*'A1 Inputs'!$C$22)/('A1 Inputs'!$C$6*((1+(1-'A1 Inputs'!$C$20)^F$33)/2)))/'A1 Terrestrial'!$C$20 -> 1.6832998 | G35: =((('A1 Orbital'!$C$5*$B35+'A1 Orbital'!$C$10+'A1 Orbital'!$C$13*$B35)*('A1 Inputs'!$C$8*(1+'A1 Inputs'!$C$8)^G$33/((1+'A1 Inputs'!$C$8)^G$33-1))+'A1 Orbital'!$C$20+'A1 Orbital'!$C$5*'A1 Inputs'!$C$21*$B35+('A1 Orbital'!$C$5*$B35+'A1 Orbital'!$C$10+'A1 Orbital'!$C$13*$B35)*'A1 Inputs'!$C$22)/('A1 Inputs'!$C$6*((1+(1-'A1 Inputs'!$C$20)^G$33)/2)))/'A1 Terrestrial'!$C$20 -> 1.5906235 | H35: =((('A1 Orbital'!$C$5*$B35+'A1 Orbital'!$C$10+'A1 Orbital'!$C$13*$B35)*('A1 Inputs'!$C$8*(1+'A1 Inputs'!$C$8)^H$33/((1+'A1 Inputs'!$C$8)^H$33-1))+'A1 Orbital'!$C$20+'A1 Orbital'!$C$5*'A1 Inputs'!$C$21*$B35+('A1 Orbital'!$C$5*$B35+'A1 Orbital'!$C$10+'A1 Orbital'!$C$13*$B35)*'A1 Inputs'!$C$22)/('A1 Inputs'!$C$6*((1+(1-'A1 Inputs'!$C$20)^H$33)/2)))/'A1 Terrestrial'!$C$20 -> 1.5736212
B36: 300 | C36: =((('A1 Orbital'!$C$5*$B36+'A1 Orbital'!$C$10+'A1 Orbital'!$C$13*$B36)*('A1 Inputs'!$C$8*(1+'A1 Inputs'!$C$8)^C$33/((1+'A1 Inputs'!$C$8)^C$33-1))+'A1 Orbital'!$C$20+'A1 Orbital'!$C$5*'A1 Inputs'!$C$21*$B36+('A1 Orbital'!$C$5*$B36+'A1 Orbital'!$C$10+'A1 Orbital'!$C$13*$B36)*'A1 Inputs'!$C$22)/('A1 Inputs'!$C$6*((1+(1-'A1 Inputs'!$C$20)^C$33)/2)))/'A1 Terrestrial'!$C$20 -> 3.0660849 | D36: =((('A1 Orbital'!$C$5*$B36+'A1 Orbital'!$C$10+'A1 Orbital'!$C$13*$B36)*('A1 Inputs'!$C$8*(1+'A1 Inputs'!$C$8)^D$33/((1+'A1 Inputs'!$C$8)^D$33-1))+'A1 Orbital'!$C$20+'A1 Orbital'!$C$5*'A1 Inputs'!$C$21*$B36+('A1 Orbital'!$C$5*$B36+'A1 Orbital'!$C$10+'A1 Orbital'!$C$13*$B36)*'A1 Inputs'!$C$22)/('A1 Inputs'!$C$6*((1+(1-'A1 Inputs'!$C$20)^D$33)/2)))/'A1 Terrestrial'!$C$20 -> 2.2918038 | E36: =((('A1 Orbital'!$C$5*$B36+'A1 Orbital'!$C$10+'A1 Orbital'!$C$13*$B36)*('A1 Inputs'!$C$8*(1+'A1 Inputs'!$C$8)^E$33/((1+'A1 Inputs'!$C$8)^E$33-1))+'A1 Orbital'!$C$20+'A1 Orbital'!$C$5*'A1 Inputs'!$C$21*$B36+('A1 Orbital'!$C$5*$B36+'A1 Orbital'!$C$10+'A1 Orbital'!$C$13*$B36)*'A1 Inputs'!$C$22)/('A1 Inputs'!$C$6*((1+(1-'A1 Inputs'!$C$20)^E$33)/2)))/'A1 Terrestrial'!$C$20 -> 1.9814845 | F36: =((('A1 Orbital'!$C$5*$B36+'A1 Orbital'!$C$10+'A1 Orbital'!$C$13*$B36)*('A1 Inputs'!$C$8*(1+'A1 Inputs'!$C$8)^F$33/((1+'A1 Inputs'!$C$8)^F$33-1))+'A1 Orbital'!$C$20+'A1 Orbital'!$C$5*'A1 Inputs'!$C$21*$B36+('A1 Orbital'!$C$5*$B36+'A1 Orbital'!$C$10+'A1 Orbital'!$C$13*$B36)*'A1 Inputs'!$C$22)/('A1 Inputs'!$C$6*((1+(1-'A1 Inputs'!$C$20)^F$33)/2)))/'A1 Terrestrial'!$C$20 -> 1.7772169 | G36: =((('A1 Orbital'!$C$5*$B36+'A1 Orbital'!$C$10+'A1 Orbital'!$C$13*$B36)*('A1 Inputs'!$C$8*(1+'A1 Inputs'!$C$8)^G$33/((1+'A1 Inputs'!$C$8)^G$33-1))+'A1 Orbital'!$C$20+'A1 Orbital'!$C$5*'A1 Inputs'!$C$21*$B36+('A1 Orbital'!$C$5*$B36+'A1 Orbital'!$C$10+'A1 Orbital'!$C$13*$B36)*'A1 Inputs'!$C$22)/('A1 Inputs'!$C$6*((1+(1-'A1 Inputs'!$C$20)^G$33)/2)))/'A1 Terrestrial'!$C$20 -> 1.6789363 | H36: =((('A1 Orbital'!$C$5*$B36+'A1 Orbital'!$C$10+'A1 Orbital'!$C$13*$B36)*('A1 Inputs'!$C$8*(1+'A1 Inputs'!$C$8)^H$33/((1+'A1 Inputs'!$C$8)^H$33-1))+'A1 Orbital'!$C$20+'A1 Orbital'!$C$5*'A1 Inputs'!$C$21*$B36+('A1 Orbital'!$C$5*$B36+'A1 Orbital'!$C$10+'A1 Orbital'!$C$13*$B36)*'A1 Inputs'!$C$22)/('A1 Inputs'!$C$6*((1+(1-'A1 Inputs'!$C$20)^H$33)/2)))/'A1 Terrestrial'!$C$20 -> 1.6606592
B37: 500 | C37: =((('A1 Orbital'!$C$5*$B37+'A1 Orbital'!$C$10+'A1 Orbital'!$C$13*$B37)*('A1 Inputs'!$C$8*(1+'A1 Inputs'!$C$8)^C$33/((1+'A1 Inputs'!$C$8)^C$33-1))+'A1 Orbital'!$C$20+'A1 Orbital'!$C$5*'A1 Inputs'!$C$21*$B37+('A1 Orbital'!$C$5*$B37+'A1 Orbital'!$C$10+'A1 Orbital'!$C$13*$B37)*'A1 Inputs'!$C$22)/('A1 Inputs'!$C$6*((1+(1-'A1 Inputs'!$C$20)^C$33)/2)))/'A1 Terrestrial'!$C$20 -> 3.3967876 | D37: =((('A1 Orbital'!$C$5*$B37+'A1 Orbital'!$C$10+'A1 Orbital'!$C$13*$B37)*('A1 Inputs'!$C$8*(1+'A1 Inputs'!$C$8)^D$33/((1+'A1 Inputs'!$C$8)^D$33-1))+'A1 Orbital'!$C$20+'A1 Orbital'!$C$5*'A1 Inputs'!$C$21*$B37+('A1 Orbital'!$C$5*$B37+'A1 Orbital'!$C$10+'A1 Orbital'!$C$13*$B37)*'A1 Inputs'!$C$22)/('A1 Inputs'!$C$6*((1+(1-'A1 Inputs'!$C$20)^D$33)/2)))/'A1 Terrestrial'!$C$20 -> 2.5368817 | E37: =((('A1 Orbital'!$C$5*$B37+'A1 Orbital'!$C$10+'A1 Orbital'!$C$13*$B37)*('A1 Inputs'!$C$8*(1+'A1 Inputs'!$C$8)^E$33/((1+'A1 Inputs'!$C$8)^E$33-1))+'A1 Orbital'!$C$20+'A1 Orbital'!$C$5*'A1 Inputs'!$C$21*$B37+('A1 Orbital'!$C$5*$B37+'A1 Orbital'!$C$10+'A1 Orbital'!$C$13*$B37)*'A1 Inputs'!$C$22)/('A1 Inputs'!$C$6*((1+(1-'A1 Inputs'!$C$20)^E$33)/2)))/'A1 Terrestrial'!$C$20 -> 2.1921348 | F37: =((('A1 Orbital'!$C$5*$B37+'A1 Orbital'!$C$10+'A1 Orbital'!$C$13*$B37)*('A1 Inputs'!$C$8*(1+'A1 Inputs'!$C$8)^F$33/((1+'A1 Inputs'!$C$8)^F$33-1))+'A1 Orbital'!$C$20+'A1 Orbital'!$C$5*'A1 Inputs'!$C$21*$B37+('A1 Orbital'!$C$5*$B37+'A1 Orbital'!$C$10+'A1 Orbital'!$C$13*$B37)*'A1 Inputs'!$C$22)/('A1 Inputs'!$C$6*((1+(1-'A1 Inputs'!$C$20)^F$33)/2)))/'A1 Terrestrial'!$C$20 -> 1.9650512 | G37: =((('A1 Orbital'!$C$5*$B37+'A1 Orbital'!$C$10+'A1 Orbital'!$C$13*$B37)*('A1 Inputs'!$C$8*(1+'A1 Inputs'!$C$8)^G$33/((1+'A1 Inputs'!$C$8)^G$33-1))+'A1 Orbital'!$C$20+'A1 Orbital'!$C$5*'A1 Inputs'!$C$21*$B37+('A1 Orbital'!$C$5*$B37+'A1 Orbital'!$C$10+'A1 Orbital'!$C$13*$B37)*'A1 Inputs'!$C$22)/('A1 Inputs'!$C$6*((1+(1-'A1 Inputs'!$C$20)^G$33)/2)))/'A1 Terrestrial'!$C$20 -> 1.855562 | H37: =((('A1 Orbital'!$C$5*$B37+'A1 Orbital'!$C$10+'A1 Orbital'!$C$13*$B37)*('A1 Inputs'!$C$8*(1+'A1 Inputs'!$C$8)^H$33/((1+'A1 Inputs'!$C$8)^H$33-1))+'A1 Orbital'!$C$20+'A1 Orbital'!$C$5*'A1 Inputs'!$C$21*$B37+('A1 Orbital'!$C$5*$B37+'A1 Orbital'!$C$10+'A1 Orbital'!$C$13*$B37)*'A1 Inputs'!$C$22)/('A1 Inputs'!$C$6*((1+(1-'A1 Inputs'!$C$20)^H$33)/2)))/'A1 Terrestrial'!$C$20 -> 1.8347351
B38: 1000 | C38: =((('A1 Orbital'!$C$5*$B38+'A1 Orbital'!$C$10+'A1 Orbital'!$C$13*$B38)*('A1 Inputs'!$C$8*(1+'A1 Inputs'!$C$8)^C$33/((1+'A1 Inputs'!$C$8)^C$33-1))+'A1 Orbital'!$C$20+'A1 Orbital'!$C$5*'A1 Inputs'!$C$21*$B38+('A1 Orbital'!$C$5*$B38+'A1 Orbital'!$C$10+'A1 Orbital'!$C$13*$B38)*'A1 Inputs'!$C$22)/('A1 Inputs'!$C$6*((1+(1-'A1 Inputs'!$C$20)^C$33)/2)))/'A1 Terrestrial'!$C$20 -> 4.2235444 | D38: =((('A1 Orbital'!$C$5*$B38+'A1 Orbital'!$C$10+'A1 Orbital'!$C$13*$B38)*('A1 Inputs'!$C$8*(1+'A1 Inputs'!$C$8)^D$33/((1+'A1 Inputs'!$C$8)^D$33-1))+'A1 Orbital'!$C$20+'A1 Orbital'!$C$5*'A1 Inputs'!$C$21*$B38+('A1 Orbital'!$C$5*$B38+'A1 Orbital'!$C$10+'A1 Orbital'!$C$13*$B38)*'A1 Inputs'!$C$22)/('A1 Inputs'!$C$6*((1+(1-'A1 Inputs'!$C$20)^D$33)/2)))/'A1 Terrestrial'!$C$20 -> 3.1495766 | E38: =((('A1 Orbital'!$C$5*$B38+'A1 Orbital'!$C$10+'A1 Orbital'!$C$13*$B38)*('A1 Inputs'!$C$8*(1+'A1 Inputs'!$C$8)^E$33/((1+'A1 Inputs'!$C$8)^E$33-1))+'A1 Orbital'!$C$20+'A1 Orbital'!$C$5*'A1 Inputs'!$C$21*$B38+('A1 Orbital'!$C$5*$B38+'A1 Orbital'!$C$10+'A1 Orbital'!$C$13*$B38)*'A1 Inputs'!$C$22)/('A1 Inputs'!$C$6*((1+(1-'A1 Inputs'!$C$20)^E$33)/2)))/'A1 Terrestrial'!$C$20 -> 2.7187606 | F38: =((('A1 Orbital'!$C$5*$B38+'A1 Orbital'!$C$10+'A1 Orbital'!$C$13*$B38)*('A1 Inputs'!$C$8*(1+'A1 Inputs'!$C$8)^F$33/((1+'A1 Inputs'!$C$8)^F$33-1))+'A1 Orbital'!$C$20+'A1 Orbital'!$C$5*'A1 Inputs'!$C$21*$B38+('A1 Orbital'!$C$5*$B38+'A1 Orbital'!$C$10+'A1 Orbital'!$C$13*$B38)*'A1 Inputs'!$C$22)/('A1 Inputs'!$C$6*((1+(1-'A1 Inputs'!$C$20)^F$33)/2)))/'A1 Terrestrial'!$C$20 -> 2.4346368 | G38: =((('A1 Orbital'!$C$5*$B38+'A1 Orbital'!$C$10+'A1 Orbital'!$C$13*$B38)*('A1 Inputs'!$C$8*(1+'A1 Inputs'!$C$8)^G$33/((1+'A1 Inputs'!$C$8)^G$33-1))+'A1 Orbital'!$C$20+'A1 Orbital'!$C$5*'A1 Inputs'!$C$21*$B38+('A1 Orbital'!$C$5*$B38+'A1 Orbital'!$C$10+'A1 Orbital'!$C$13*$B38)*'A1 Inputs'!$C$22)/('A1 Inputs'!$C$6*((1+(1-'A1 Inputs'!$C$20)^G$33)/2)))/'A1 Terrestrial'!$C$20 -> 2.2971263 | H38: =((('A1 Orbital'!$C$5*$B38+'A1 Orbital'!$C$10+'A1 Orbital'!$C$13*$B38)*('A1 Inputs'!$C$8*(1+'A1 Inputs'!$C$8)^H$33/((1+'A1 Inputs'!$C$8)^H$33-1))+'A1 Orbital'!$C$20+'A1 Orbital'!$C$5*'A1 Inputs'!$C$21*$B38+('A1 Orbital'!$C$5*$B38+'A1 Orbital'!$C$10+'A1 Orbital'!$C$13*$B38)*'A1 Inputs'!$C$22)/('A1 Inputs'!$C$6*((1+(1-'A1 Inputs'!$C$20)^H$33)/2)))/'A1 Terrestrial'!$C$20 -> 2.2699249
B39: 2000 | C39: =((('A1 Orbital'!$C$5*$B39+'A1 Orbital'!$C$10+'A1 Orbital'!$C$13*$B39)*('A1 Inputs'!$C$8*(1+'A1 Inputs'!$C$8)^C$33/((1+'A1 Inputs'!$C$8)^C$33-1))+'A1 Orbital'!$C$20+'A1 Orbital'!$C$5*'A1 Inputs'!$C$21*$B39+('A1 Orbital'!$C$5*$B39+'A1 Orbital'!$C$10+'A1 Orbital'!$C$13*$B39)*'A1 Inputs'!$C$22)/('A1 Inputs'!$C$6*((1+(1-'A1 Inputs'!$C$20)^C$33)/2)))/'A1 Terrestrial'!$C$20 -> 5.877058 | D39: =((('A1 Orbital'!$C$5*$B39+'A1 Orbital'!$C$10+'A1 Orbital'!$C$13*$B39)*('A1 Inputs'!$C$8*(1+'A1 Inputs'!$C$8)^D$33/((1+'A1 Inputs'!$C$8)^D$33-1))+'A1 Orbital'!$C$20+'A1 Orbital'!$C$5*'A1 Inputs'!$C$21*$B39+('A1 Orbital'!$C$5*$B39+'A1 Orbital'!$C$10+'A1 Orbital'!$C$13*$B39)*'A1 Inputs'!$C$22)/('A1 Inputs'!$C$6*((1+(1-'A1 Inputs'!$C$20)^D$33)/2)))/'A1 Terrestrial'!$C$20 -> 4.3749664 | E39: =((('A1 Orbital'!$C$5*$B39+'A1 Orbital'!$C$10+'A1 Orbital'!$C$13*$B39)*('A1 Inputs'!$C$8*(1+'A1 Inputs'!$C$8)^E$33/((1+'A1 Inputs'!$C$8)^E$33-1))+'A1 Orbital'!$C$20+'A1 Orbital'!$C$5*'A1 Inputs'!$C$21*$B39+('A1 Orbital'!$C$5*$B39+'A1 Orbital'!$C$10+'A1 Orbital'!$C$13*$B39)*'A1 Inputs'!$C$22)/('A1 Inputs'!$C$6*((1+(1-'A1 Inputs'!$C$20)^E$33)/2)))/'A1 Terrestrial'!$C$20 -> 3.7720122 | F39: =((('A1 Orbital'!$C$5*$B39+'A1 Orbital'!$C$10+'A1 Orbital'!$C$13*$B39)*('A1 Inputs'!$C$8*(1+'A1 Inputs'!$C$8)^F$33/((1+'A1 Inputs'!$C$8)^F$33-1))+'A1 Orbital'!$C$20+'A1 Orbital'!$C$5*'A1 Inputs'!$C$21*$B39+('A1 Orbital'!$C$5*$B39+'A1 Orbital'!$C$10+'A1 Orbital'!$C$13*$B39)*'A1 Inputs'!$C$22)/('A1 Inputs'!$C$6*((1+(1-'A1 Inputs'!$C$20)^F$33)/2)))/'A1 Terrestrial'!$C$20 -> 3.373808 | G39: =((('A1 Orbital'!$C$5*$B39+'A1 Orbital'!$C$10+'A1 Orbital'!$C$13*$B39)*('A1 Inputs'!$C$8*(1+'A1 Inputs'!$C$8)^G$33/((1+'A1 Inputs'!$C$8)^G$33-1))+'A1 Orbital'!$C$20+'A1 Orbital'!$C$5*'A1 Inputs'!$C$21*$B39+('A1 Orbital'!$C$5*$B39+'A1 Orbital'!$C$10+'A1 Orbital'!$C$13*$B39)*'A1 Inputs'!$C$22)/('A1 Inputs'!$C$6*((1+(1-'A1 Inputs'!$C$20)^G$33)/2)))/'A1 Terrestrial'!$C$20 -> 3.1802548 | H39: =((('A1 Orbital'!$C$5*$B39+'A1 Orbital'!$C$10+'A1 Orbital'!$C$13*$B39)*('A1 Inputs'!$C$8*(1+'A1 Inputs'!$C$8)^H$33/((1+'A1 Inputs'!$C$8)^H$33-1))+'A1 Orbital'!$C$20+'A1 Orbital'!$C$5*'A1 Inputs'!$C$21*$B39+('A1 Orbital'!$C$5*$B39+'A1 Orbital'!$C$10+'A1 Orbital'!$C$13*$B39)*'A1 Inputs'!$C$22)/('A1 Inputs'!$C$6*((1+(1-'A1 Inputs'!$C$20)^H$33)/2)))/'A1 Terrestrial'!$C$20 -> 3.1403046
B40: 5000 | C40: =((('A1 Orbital'!$C$5*$B40+'A1 Orbital'!$C$10+'A1 Orbital'!$C$13*$B40)*('A1 Inputs'!$C$8*(1+'A1 Inputs'!$C$8)^C$33/((1+'A1 Inputs'!$C$8)^C$33-1))+'A1 Orbital'!$C$20+'A1 Orbital'!$C$5*'A1 Inputs'!$C$21*$B40+('A1 Orbital'!$C$5*$B40+'A1 Orbital'!$C$10+'A1 Orbital'!$C$13*$B40)*'A1 Inputs'!$C$22)/('A1 Inputs'!$C$6*((1+(1-'A1 Inputs'!$C$20)^C$33)/2)))/'A1 Terrestrial'!$C$20 -> 10.837599 | D40: =((('A1 Orbital'!$C$5*$B40+'A1 Orbital'!$C$10+'A1 Orbital'!$C$13*$B40)*('A1 Inputs'!$C$8*(1+'A1 Inputs'!$C$8)^D$33/((1+'A1 Inputs'!$C$8)^D$33-1))+'A1 Orbital'!$C$20+'A1 Orbital'!$C$5*'A1 Inputs'!$C$21*$B40+('A1 Orbital'!$C$5*$B40+'A1 Orbital'!$C$10+'A1 Orbital'!$C$13*$B40)*'A1 Inputs'!$C$22)/('A1 Inputs'!$C$6*((1+(1-'A1 Inputs'!$C$20)^D$33)/2)))/'A1 Terrestrial'!$C$20 -> 8.0511358 | E40: =((('A1 Orbital'!$C$5*$B40+'A1 Orbital'!$C$10+'A1 Orbital'!$C$13*$B40)*('A1 Inputs'!$C$8*(1+'A1 Inputs'!$C$8)^E$33/((1+'A1 Inputs'!$C$8)^E$33-1))+'A1 Orbital'!$C$20+'A1 Orbital'!$C$5*'A1 Inputs'!$C$21*$B40+('A1 Orbital'!$C$5*$B40+'A1 Orbital'!$C$10+'A1 Orbital'!$C$13*$B40)*'A1 Inputs'!$C$22)/('A1 Inputs'!$C$6*((1+(1-'A1 Inputs'!$C$20)^E$33)/2)))/'A1 Terrestrial'!$C$20 -> 6.9317672 | F40: =((('A1 Orbital'!$C$5*$B40+'A1 Orbital'!$C$10+'A1 Orbital'!$C$13*$B40)*('A1 Inputs'!$C$8*(1+'A1 Inputs'!$C$8)^F$33/((1+'A1 Inputs'!$C$8)^F$33-1))+'A1 Orbital'!$C$20+'A1 Orbital'!$C$5*'A1 Inputs'!$C$21*$B40+('A1 Orbital'!$C$5*$B40+'A1 Orbital'!$C$10+'A1 Orbital'!$C$13*$B40)*'A1 Inputs'!$C$22)/('A1 Inputs'!$C$6*((1+(1-'A1 Inputs'!$C$20)^F$33)/2)))/'A1 Terrestrial'!$C$20 -> 6.1913218 | G40: =((('A1 Orbital'!$C$5*$B40+'A1 Orbital'!$C$10+'A1 Orbital'!$C$13*$B40)*('A1 Inputs'!$C$8*(1+'A1 Inputs'!$C$8)^G$33/((1+'A1 Inputs'!$C$8)^G$33-1))+'A1 Orbital'!$C$20+'A1 Orbital'!$C$5*'A1 Inputs'!$C$21*$B40+('A1 Orbital'!$C$5*$B40+'A1 Orbital'!$C$10+'A1 Orbital'!$C$13*$B40)*'A1 Inputs'!$C$22)/('A1 Inputs'!$C$6*((1+(1-'A1 Inputs'!$C$20)^G$33)/2)))/'A1 Terrestrial'!$C$20 -> 5.8296404 | H40: =((('A1 Orbital'!$C$5*$B40+'A1 Orbital'!$C$10+'A1 Orbital'!$C$13*$B40)*('A1 Inputs'!$C$8*(1+'A1 Inputs'!$C$8)^H$33/((1+'A1 Inputs'!$C$8)^H$33-1))+'A1 Orbital'!$C$20+'A1 Orbital'!$C$5*'A1 Inputs'!$C$21*$B40+('A1 Orbital'!$C$5*$B40+'A1 Orbital'!$C$10+'A1 Orbital'!$C$13*$B40)*'A1 Inputs'!$C$22)/('A1 Inputs'!$C$6*((1+(1-'A1 Inputs'!$C$20)^H$33)/2)))/'A1 Terrestrial'!$C$20 -> 5.7514436
B41: 7000 | C41: =((('A1 Orbital'!$C$5*$B41+'A1 Orbital'!$C$10+'A1 Orbital'!$C$13*$B41)*('A1 Inputs'!$C$8*(1+'A1 Inputs'!$C$8)^C$33/((1+'A1 Inputs'!$C$8)^C$33-1))+'A1 Orbital'!$C$20+'A1 Orbital'!$C$5*'A1 Inputs'!$C$21*$B41+('A1 Orbital'!$C$5*$B41+'A1 Orbital'!$C$10+'A1 Orbital'!$C$13*$B41)*'A1 Inputs'!$C$22)/('A1 Inputs'!$C$6*((1+(1-'A1 Inputs'!$C$20)^C$33)/2)))/'A1 Terrestrial'!$C$20 -> 14.144626 | D41: =((('A1 Orbital'!$C$5*$B41+'A1 Orbital'!$C$10+'A1 Orbital'!$C$13*$B41)*('A1 Inputs'!$C$8*(1+'A1 Inputs'!$C$8)^D$33/((1+'A1 Inputs'!$C$8)^D$33-1))+'A1 Orbital'!$C$20+'A1 Orbital'!$C$5*'A1 Inputs'!$C$21*$B41+('A1 Orbital'!$C$5*$B41+'A1 Orbital'!$C$10+'A1 Orbital'!$C$13*$B41)*'A1 Inputs'!$C$22)/('A1 Inputs'!$C$6*((1+(1-'A1 Inputs'!$C$20)^D$33)/2)))/'A1 Terrestrial'!$C$20 -> 10.501915 | E41: =((('A1 Orbital'!$C$5*$B41+'A1 Orbital'!$C$10+'A1 Orbital'!$C$13*$B41)*('A1 Inputs'!$C$8*(1+'A1 Inputs'!$C$8)^E$33/((1+'A1 Inputs'!$C$8)^E$33-1))+'A1 Orbital'!$C$20+'A1 Orbital'!$C$5*'A1 Inputs'!$C$21*$B41+('A1 Orbital'!$C$5*$B41+'A1 Orbital'!$C$10+'A1 Orbital'!$C$13*$B41)*'A1 Inputs'!$C$22)/('A1 Inputs'!$C$6*((1+(1-'A1 Inputs'!$C$20)^E$33)/2)))/'A1 Terrestrial'!$C$20 -> 9.0382704 | F41: =((('A1 Orbital'!$C$5*$B41+'A1 Orbital'!$C$10+'A1 Orbital'!$C$13*$B41)*('A1 Inputs'!$C$8*(1+'A1 Inputs'!$C$8)^F$33/((1+'A1 Inputs'!$C$8)^F$33-1))+'A1 Orbital'!$C$20+'A1 Orbital'!$C$5*'A1 Inputs'!$C$21*$B41+('A1 Orbital'!$C$5*$B41+'A1 Orbital'!$C$10+'A1 Orbital'!$C$13*$B41)*'A1 Inputs'!$C$22)/('A1 Inputs'!$C$6*((1+(1-'A1 Inputs'!$C$20)^F$33)/2)))/'A1 Terrestrial'!$C$20 -> 8.0696642 | G41: =((('A1 Orbital'!$C$5*$B41+'A1 Orbital'!$C$10+'A1 Orbital'!$C$13*$B41)*('A1 Inputs'!$C$8*(1+'A1 Inputs'!$C$8)^G$33/((1+'A1 Inputs'!$C$8)^G$33-1))+'A1 Orbital'!$C$20+'A1 Orbital'!$C$5*'A1 Inputs'!$C$21*$B41+('A1 Orbital'!$C$5*$B41+'A1 Orbital'!$C$10+'A1 Orbital'!$C$13*$B41)*'A1 Inputs'!$C$22)/('A1 Inputs'!$C$6*((1+(1-'A1 Inputs'!$C$20)^G$33)/2)))/'A1 Terrestrial'!$C$20 -> 7.5958974 | H41: =((('A1 Orbital'!$C$5*$B41+'A1 Orbital'!$C$10+'A1 Orbital'!$C$13*$B41)*('A1 Inputs'!$C$8*(1+'A1 Inputs'!$C$8)^H$33/((1+'A1 Inputs'!$C$8)^H$33-1))+'A1 Orbital'!$C$20+'A1 Orbital'!$C$5*'A1 Inputs'!$C$21*$B41+('A1 Orbital'!$C$5*$B41+'A1 Orbital'!$C$10+'A1 Orbital'!$C$13*$B41)*'A1 Inputs'!$C$22)/('A1 Inputs'!$C$6*((1+(1-'A1 Inputs'!$C$20)^H$33)/2)))/'A1 Terrestrial'!$C$20 -> 7.492203
B43: TIE-OUT: base cell (1,000 $/kg, 10-yr life) = Orbital Build!C28 ÷ Terrestrial Build!C20 = the headline ~2.4x per MW-year.
B44: READING: longer life lowers the annualized burden, but orbital stays >1x even at 20-yr life + low launch — asset life alone cannot offset the compute+radiator+re-launch stack. Parity needs launch, specific power, AND life together (see crossover #1 above).
B48: Scenario launch cost ($/kg): | C48: 300 | D48: [TGT] forward Starship target
B49: LONG-RUN SCENARIO (INFERENCE) — Orbital ÷ Terrestrial annual cost, as the bet's two levers move
B50: Forward inputs: orbital hardware $/W falls (vertical integration, terafab, scale) and terrestrial $/W rises (grid scarcity, transformers, permitting); launch held at the scenario cell above. Green <1.0x = orbit cheaper. INFERENCE ONLY — frontier training stays on Earth (bandwidth-bound, see Effective Compute).
B51: Orbital HW $/W \ Terrestrial $/W -> | C51: 38 | D51: 50 | E51: 70 | F51: 100 | G51: 150
B52: 49 | C52: =(('A1 Orbital'!$C$5*$C$48+(('A1 Inputs'!$C$6*1000000)*$B52)+'A1 Orbital'!$C$13*$C$48)*'A1 Orbital'!$C$18+(('A1 Inputs'!$C$6*1000000)*$B52)*'A1 Inputs'!$C$21+'A1 Orbital'!$C$5*'A1 Inputs'!$C$21*$C$48+('A1 Orbital'!$C$5*$C$48+(('A1 Inputs'!$C$6*1000000)*$B52)+'A1 Orbital'!$C$13*$C$48)*'A1 Inputs'!$C$22)/((('A1 Inputs'!$C$6*1000000)*C$51)*'A1 Inputs'!$C$32*'A1 Terrestrial'!$C$9+(('A1 Inputs'!$C$6*1000000)*C$51)*(1-'A1 Inputs'!$C$32)*'A1 Terrestrial'!$C$10+'A1 Terrestrial'!$C$14+(('A1 Inputs'!$C$6*1000000)*C$51)*'A1 Inputs'!$C$35) -> 1.5784615 | D52: =(('A1 Orbital'!$C$5*$C$48+(('A1 Inputs'!$C$6*1000000)*$B52)+'A1 Orbital'!$C$13*$C$48)*'A1 Orbital'!$C$18+(('A1 Inputs'!$C$6*1000000)*$B52)*'A1 Inputs'!$C$21+'A1 Orbital'!$C$5*'A1 Inputs'!$C$21*$C$48+('A1 Orbital'!$C$5*$C$48+(('A1 Inputs'!$C$6*1000000)*$B52)+'A1 Orbital'!$C$13*$C$48)*'A1 Inputs'!$C$22)/((('A1 Inputs'!$C$6*1000000)*D$51)*'A1 Inputs'!$C$32*'A1 Terrestrial'!$C$9+(('A1 Inputs'!$C$6*1000000)*D$51)*(1-'A1 Inputs'!$C$32)*'A1 Terrestrial'!$C$10+'A1 Terrestrial'!$C$14+(('A1 Inputs'!$C$6*1000000)*D$51)*'A1 Inputs'!$C$35) -> 1.2237799 | E52: =(('A1 Orbital'!$C$5*$C$48+(('A1 Inputs'!$C$6*1000000)*$B52)+'A1 Orbital'!$C$13*$C$48)*'A1 Orbital'!$C$18+(('A1 Inputs'!$C$6*1000000)*$B52)*'A1 Inputs'!$C$21+'A1 Orbital'!$C$5*'A1 Inputs'!$C$21*$C$48+('A1 Orbital'!$C$5*$C$48+(('A1 Inputs'!$C$6*1000000)*$B52)+'A1 Orbital'!$C$13*$C$48)*'A1 Inputs'!$C$22)/((('A1 Inputs'!$C$6*1000000)*E$51)*'A1 Inputs'!$C$32*'A1 Terrestrial'!$C$9+(('A1 Inputs'!$C$6*1000000)*E$51)*(1-'A1 Inputs'!$C$32)*'A1 Terrestrial'!$C$10+'A1 Terrestrial'!$C$14+(('A1 Inputs'!$C$6*1000000)*E$51)*'A1 Inputs'!$C$35) -> 0.89034459 | F52: =(('A1 Orbital'!$C$5*$C$48+(('A1 Inputs'!$C$6*1000000)*$B52)+'A1 Orbital'!$C$13*$C$48)*'A1 Orbital'!$C$18+(('A1 Inputs'!$C$6*1000000)*$B52)*'A1 Inputs'!$C$21+'A1 Orbital'!$C$5*'A1 Inputs'!$C$21*$C$48+('A1 Orbital'!$C$5*$C$48+(('A1 Inputs'!$C$6*1000000)*$B52)+'A1 Orbital'!$C$13*$C$48)*'A1 Inputs'!$C$22)/((('A1 Inputs'!$C$6*1000000)*F$51)*'A1 Inputs'!$C$32*'A1 Terrestrial'!$C$9+(('A1 Inputs'!$C$6*1000000)*F$51)*(1-'A1 Inputs'!$C$32)*'A1 Terrestrial'!$C$10+'A1 Terrestrial'!$C$14+(('A1 Inputs'!$C$6*1000000)*F$51)*'A1 Inputs'!$C$35) -> 0.63203495 | G52: =(('A1 Orbital'!$C$5*$C$48+(('A1 Inputs'!$C$6*1000000)*$B52)+'A1 Orbital'!$C$13*$C$48)*'A1 Orbital'!$C$18+(('A1 Inputs'!$C$6*1000000)*$B52)*'A1 Inputs'!$C$21+'A1 Orbital'!$C$5*'A1 Inputs'!$C$21*$C$48+('A1 Orbital'!$C$5*$C$48+(('A1 Inputs'!$C$6*1000000)*$B52)+'A1 Orbital'!$C$13*$C$48)*'A1 Inputs'!$C$22)/((('A1 Inputs'!$C$6*1000000)*G$51)*'A1 Inputs'!$C$32*'A1 Terrestrial'!$C$9+(('A1 Inputs'!$C$6*1000000)*G$51)*(1-'A1 Inputs'!$C$32)*'A1 Terrestrial'!$C$10+'A1 Terrestrial'!$C$14+(('A1 Inputs'!$C$6*1000000)*G$51)*'A1 Inputs'!$C$35) -> 0.42603199
...

Sheet A2 Inputs
B2: INPUTS & ASSUMPTIONS
B3: Most cost inputs here are [SPX-IN] placeholders — replace with real Bastrop figures to make it a live tool.
B5: COMPONENT & VOLUME
B6: Component | C6: RF packaging | E6: [FACT] | F6: Bastrop insourcing RF-chip packaging; line targeted end-2026
B7: Year-1 annual volume | C7: 2000000 | D7: units/yr | E7: [SPX-IN] | F7: Illustrative; tie to ~15,000 dishes/day = ~5.5M/yr terminal run-rate
B8: Annual volume growth | C8: 0.25 | D8: %/yr | E8: [EST] | F8: US kit output +62% over 9 mo in 2025; assume 25%/yr
B9: Analysis horizon (structural) | C9: 7 | D9: years | E9: [EST] | F9: Standard capex horizon
B10: Discount rate (WACC) | C10: ='Global Assumptions'!$C$6 -> 0.12 | D10: %/yr | E10: [SPX-IN] | F10: Placeholder cost of capital
B12: BUY (outsource) PATH
B13: Outsourced unit price (Y1) | C13: 4.5 | D13: $/unit | E13: [SPX-IN] | F13: Illustrative current vendor price incl margin
B14: Vendor price escalation | C14: 0.03 | D14: %/yr | E14: [EST] | F14: Annual price increase
B16: BUILD (insource) PATH
B17: Line capex (equipment+install) | C17: 35000000 | D17: $ | E17: [SPX-IN] | F17: Illustrative packaging line; replace w/ real equipment quote
B18: Equipment depreciation life (ref. only) | C18: 7 | D18: years | E18: [EST] | F18: Reference only — this is a pure cash NPV model and does not depreciate. Shown for context.
B19: In-house unit cost at Y1 volume | C19: 3.6 | D19: $/unit | E19: [SPX-IN] | F19: BOM+labor+overhead at the Year-1 cumulative volume anchor (not unit 1). Learning applies to doublings beyond Y1.
B20: Learning rate (Wright's law) | C20: 0.85 | D20: % | E20: [FACT] | F20: Electronics typically 85-90%: 15% cost cut per cumulative doubling
B21: Year-1 yield | C21: 0.8 | D21: % | E21: [EST] | F21: Ramp yield; improves to mature
B22: Mature yield | C22: 0.97 | D22: % | E22: [EST] | F22: Steady-state
B23: Fixed line opex | C23: 0.06 | D23: %capex/yr | E23: [EST] | F23: Maintenance/utilities/staff as % of capex
B26: J. Shapiro · Independent work sample · illustrative inputs labeled [SPX-IN]

Sheet A2 BuildVsBuy
B2: BUILD vs BUY — ANNUAL CASH FLOWS
B4: Year | C4: 1 | D4: 2 | E4: 3 | F4: 4 | G4: 5 | H4: 6 | I4: 7
B5: Annual volume (units) | C5: ='A2 Inputs'!$C$7 -> 2000000 | D5: =C5*(1+'A2 Inputs'!$C$8) -> 2500000 | E5: =D5*(1+'A2 Inputs'!$C$8) -> 3125000 | F5: =E5*(1+'A2 Inputs'!$C$8) -> 3906250 | G5: =F5*(1+'A2 Inputs'!$C$8) -> 4882812.5 | H5: =G5*(1+'A2 Inputs'!$C$8) -> 6103515.6 | I5: =H5*(1+'A2 Inputs'!$C$8) -> 7629394.5
B6: Cumulative volume | C6: =C5 -> 2000000 | D6: =C6+D5 -> 4500000 | E6: =D6+E5 -> 7625000 | F6: =E6+F5 -> 11531250 | G6: =F6+G5 -> 16414062 | H6: =G6+H5 -> 22517578 | I6: =H6+I5 -> 30146973
B8: BUY: outsourced cost ($) | C8: =C5*'A2 Inputs'!$C$13*(1+'A2 Inputs'!$C$14)^0 -> 9000000 | D8: =D5*'A2 Inputs'!$C$13*(1+'A2 Inputs'!$C$14)^1 -> 11587500 | E8: =E5*'A2 Inputs'!$C$13*(1+'A2 Inputs'!$C$14)^2 -> 14918906 | F8: =F5*'A2 Inputs'!$C$13*(1+'A2 Inputs'!$C$14)^3 -> 19208092 | G8: =G5*'A2 Inputs'!$C$13*(1+'A2 Inputs'!$C$14)^4 -> 24730418 | H8: =H5*'A2 Inputs'!$C$13*(1+'A2 Inputs'!$C$14)^5 -> 31840413 | I8: =I5*'A2 Inputs'!$C$13*(1+'A2 Inputs'!$C$14)^6 -> 40994532
B10: BUILD: in-house unit cost ($) | C10: ='A2 Inputs'!$C$19*((C6/$C$6)^(LOG('A2 Inputs'!$C$20,2)))/('A2 Inputs'!$C$21+('A2 Inputs'!$C$22-'A2 Inputs'!$C$21)*MIN(1,0/3)) -> 4.5 | D10: ='A2 Inputs'!$C$19*((D6/$C$6)^(LOG('A2 Inputs'!$C$20,2)))/('A2 Inputs'!$C$21+('A2 Inputs'!$C$22-'A2 Inputs'!$C$21)*MIN(1,1/3)) -> 3.47469 | E10: ='A2 Inputs'!$C$19*((E6/$C$6)^(LOG('A2 Inputs'!$C$20,2)))/('A2 Inputs'!$C$21+('A2 Inputs'!$C$22-'A2 Inputs'!$C$21)*MIN(1,2/3)) -> 2.8800477 | F10: ='A2 Inputs'!$C$19*((F6/$C$6)^(LOG('A2 Inputs'!$C$20,2)))/('A2 Inputs'!$C$21+('A2 Inputs'!$C$22-'A2 Inputs'!$C$21)*MIN(1,3/3)) -> 2.4611536 | G10: ='A2 Inputs'!$C$19*((G6/$C$6)^(LOG('A2 Inputs'!$C$20,2)))/('A2 Inputs'!$C$21+('A2 Inputs'!$C$22-'A2 Inputs'!$C$21)*MIN(1,4/3)) -> 2.2656139 | H10: ='A2 Inputs'!$C$19*((H6/$C$6)^(LOG('A2 Inputs'!$C$20,2)))/('A2 Inputs'!$C$21+('A2 Inputs'!$C$22-'A2 Inputs'!$C$21)*MIN(1,5/3)) -> 2.1037421 | I10: ='A2 Inputs'!$C$19*((I6/$C$6)^(LOG('A2 Inputs'!$C$20,2)))/('A2 Inputs'!$C$21+('A2 Inputs'!$C$22-'A2 Inputs'!$C$21)*MIN(1,6/3)) -> 1.9646292
B11: BUILD: variable cost ($) | C11: =C5*C10 -> 9000000 | D11: =D5*D10 -> 8686725.1 | E11: =E5*E10 -> 9000149 | F11: =F5*F10 -> 9613881.4 | G11: =G5*G10 -> 11062568 | H11: =H5*H10 -> 12840223 | I11: =I5*I10 -> 14988931
B12: BUILD: fixed line opex ($) | C12: ='A2 Inputs'!$C$17*'A2 Inputs'!$C$23 -> 2100000 | D12: ='A2 Inputs'!$C$17*'A2 Inputs'!$C$23 -> 2100000 | E12: ='A2 Inputs'!$C$17*'A2 Inputs'!$C$23 -> 2100000 | F12: ='A2 Inputs'!$C$17*'A2 Inputs'!$C$23 -> 2100000 | G12: ='A2 Inputs'!$C$17*'A2 Inputs'!$C$23 -> 2100000 | H12: ='A2 Inputs'!$C$17*'A2 Inputs'!$C$23 -> 2100000 | I12: ='A2 Inputs'!$C$17*'A2 Inputs'!$C$23 -> 2100000
B13: BUILD: capex ($) | C13: ='A2 Inputs'!$C$17 -> 35000000 | D13: =0 -> 0 | E13: =0 -> 0 | F13: =0 -> 0 | G13: =0 -> 0 | H13: =0 -> 0 | I13: =0 -> 0
B14: BUILD: total cost ($) | C14: =C11+C12+C13 -> 46100000 | D14: =D11+D12+D13 -> 10786725 | E14: =E11+E12+E13 -> 11100149 | F14: =F11+F12+F13 -> 11713881 | G14: =G11+G12+G13 -> 13162568 | H14: =H11+H12+H13 -> 14940223 | I14: =I11+I12+I13 -> 17088931
B16: Annual saving (Buy - Build) ($) | C16: =C8-C14 -> -37100000 | D16: =D8-D14 -> 800774.91 | E16: =E8-E14 -> 3818757.3 | F16: =F8-F14 -> 7494210.4 | G16: =G8-G14 -> 11567850 | H16: =H8-H14 -> 16900191 | I16: =I8-I14 -> 23905601
B17: Discounted saving ($) | C17: =C16/(1+'A2 Inputs'!$C$10)^1 -> -33125000 | D17: =D16/(1+'A2 Inputs'!$C$10)^2 -> 638372.86 | E17: =E16/(1+'A2 Inputs'!$C$10)^3 -> 2718116 | F17: =F16/(1+'A2 Inputs'!$C$10)^4 -> 4762706.2 | G17: =G16/(1+'A2 Inputs'!$C$10)^5 -> 6563909 | H17: =H16/(1+'A2 Inputs'!$C$10)^6 -> 8562162.5 | I17: =I16/(1+'A2 Inputs'!$C$10)^7 -> 10813680
B18: Cumulative NPV ($) | C18: =C17 -> -33125000 | D18: =C18+D17 -> -32486627 | E18: =D18+E17 -> -29768511 | F18: =E18+F17 -> -25005805 | G18: =F18+G17 -> -18441896 | H18: =G18+H17 -> -9879733.4 | I18: =H18+I17 -> 933946.48
B21: SUMMARY
B22: Net NPV of insourcing ($) | C22: =I18 -> 933946.48
B23: Mature in-house unit cost ($) | C23: =I10 -> 1.9646292
B24: Mature outsourced price ($) | C24: =I8/I5 -> 5.3732353
B25: Unit cost advantage at maturity ($) | C25: =C24-C23 -> 3.4086062
B28: J. Shapiro · Independent work sample · illustrative inputs labeled [SPX-IN]

Sheet A2 CostCurve
B2: COST-DOWN CURVE & NPV SENSITIVITY
B3: Each (learning rate × Y1 volume) cell reproduces the main tab's per-year logic exactly: 25%/yr volume growth, yield ramp,
B4: normalized Wright's-law curve, per-year discounting. The base case (0.85 / 2.0M) ties to tab 2's headline NPV.
B6: NPV of insourcing ($), 7-yr horizon
B7: LR \ Y1 volume | C7: 1000000 | D7: 2000000 | E7: 3500000 | F7: 5500000 | G7: 8000000
B8: 0.9 | C8: =SUM(C24:I24) -> -23201618 | D8: =SUM(C33:I33) -> -5569347 | E8: =SUM(C42:I42) -> 20879059 | F8: =SUM(C51:I51) -> 56143601 | G8: =SUM(C60:I60) -> 1.0022428e+08
B9: 0.88 | C9: =SUM(C69:I69) -> -21855644 | D9: =SUM(C78:I78) -> -2877399 | E9: =SUM(C87:I87) -> 25589968 | F9: =SUM(C96:I96) -> 63546458 | G9: =SUM(C105:I105) -> 1.1099207e+08
B10: 0.85 | C10: =SUM(C114:I114) -> -19949971 | D10: =SUM(C123:I123) -> 933946.48 | E10: =SUM(C132:I132) -> 32259823 | F10: =SUM(C141:I141) -> 74027658 | G10: =SUM(C150:I150) -> 1.2623745e+08
B11: 0.82 | C11: =SUM(C159:I159) -> -18174658 | D11: =SUM(C168:I168) -> 4484573.4 | E11: =SUM(C177:I177) -> 38473420 | F11: =SUM(C186:I186) -> 83791882 | G11: =SUM(C195:I195) -> 1.4043996e+08
B12: 0.8 | C12: =SUM(C204:I204) -> -17060490 | D12: =SUM(C213:I213) -> 6712909.7 | E12: =SUM(C222:I222) -> 42373008 | F12: =SUM(C231:I231) -> 89919807 | G12: =SUM(C240:I240) -> 1.493533e+08
B14: TIE-OUT: base cell (LR 0.85 / V1 2,000,000) equals tab 2 headline Net NPV by construction (same per-year math). Holds at the DEFAULT LR; the grid varies LR independently, so changing Inputs!C20 moves the headline but not this base cell.
B15: READING: green = insourcing NPV-positive; red = BUY wins. Insourcing needs BOTH adequate volume AND a steep
B16: enough learning rate to amortize the line's fixed capex; below breakeven volume the line is underutilized and BUY wins.
B17: WHAT I'D NEED FROM SPACEX: real line capex, current outsourced price, first-block in-house cost, yield ramp, committed volume. | C17: Y1 | D17: Y2 | E17: Y3 | F17: Y4 | G17: Y5 | H17: Y6 | I17: Y7
B18: vol_t | C18: =1000000*(1+'A2 Inputs'!$C$8)^0 -> 1000000 | D18: =1000000*(1+'A2 Inputs'!$C$8)^1 -> 1250000 | E18: =1000000*(1+'A2 Inputs'!$C$8)^2 -> 1562500 | F18: =1000000*(1+'A2 Inputs'!$C$8)^3 -> 1953125 | G18: =1000000*(1+'A2 Inputs'!$C$8)^4 -> 2441406.2 | H18: =1000000*(1+'A2 Inputs'!$C$8)^5 -> 3051757.8 | I18: =1000000*(1+'A2 Inputs'!$C$8)^6 -> 3814697.3
B19: cumvol_t | C19: =1000000*((1+'A2 Inputs'!$C$8)^1-1)/'A2 Inputs'!$C$8 -> 1000000 | D19: =1000000*((1+'A2 Inputs'!$C$8)^2-1)/'A2 Inputs'!$C$8 -> 2250000 | E19: =1000000*((1+'A2 Inputs'!$C$8)^3-1)/'A2 Inputs'!$C$8 -> 3812500 | F19: =1000000*((1+'A2 Inputs'!$C$8)^4-1)/'A2 Inputs'!$C$8 -> 5765625 | G19: =1000000*((1+'A2 Inputs'!$C$8)^5-1)/'A2 Inputs'!$C$8 -> 8207031.2 | H19: =1000000*((1+'A2 Inputs'!$C$8)^6-1)/'A2 Inputs'!$C$8 -> 11258789 | I19: =1000000*((1+'A2 Inputs'!$C$8)^7-1)/'A2 Inputs'!$C$8 -> 15073486
B20: yield_t | C20: ='A2 Inputs'!$C$21+('A2 Inputs'!$C$22-'A2 Inputs'!$C$21)*MIN(1,(0)/3) -> 0.8 | D20: ='A2 Inputs'!$C$21+('A2 Inputs'!$C$22-'A2 Inputs'!$C$21)*MIN(1,(1)/3) -> 0.85666667 | E20: ='A2 Inputs'!$C$21+('A2 Inputs'!$C$22-'A2 Inputs'!$C$21)*MIN(1,(2)/3) -> 0.91333333 | F20: ='A2 Inputs'!$C$21+('A2 Inputs'!$C$22-'A2 Inputs'!$C$21)*MIN(1,(3)/3) -> 0.97 | G20: ='A2 Inputs'!$C$21+('A2 Inputs'!$C$22-'A2 Inputs'!$C$21)*MIN(1,(4)/3) -> 0.97 | H20: ='A2 Inputs'!$C$21+('A2 Inputs'!$C$22-'A2 Inputs'!$C$21)*MIN(1,(5)/3) -> 0.97 | I20: ='A2 Inputs'!$C$21+('A2 Inputs'!$C$22-'A2 Inputs'!$C$21)*MIN(1,(6)/3) -> 0.97
B21: inhouse_t | C21: ='A2 Inputs'!$C$19*((C19/1000000)^(LOG(0.9,2)))/C20 -> 4.5 | D21: ='A2 Inputs'!$C$19*((D19/1000000)^(LOG(0.9,2)))/D20 -> 3.7149913 | E21: ='A2 Inputs'!$C$19*((E19/1000000)^(LOG(0.9,2)))/E20 -> 3.2160848 | F21: ='A2 Inputs'!$C$19*((F19/1000000)^(LOG(0.9,2)))/F20 -> 2.8436737 | G21: ='A2 Inputs'!$C$19*((G19/1000000)^(LOG(0.9,2)))/G20 -> 2.69508 | H21: ='A2 Inputs'!$C$19*((H19/1000000)^(LOG(0.9,2)))/H20 -> 2.5686254 | I21: ='A2 Inputs'!$C$19*((I19/1000000)^(LOG(0.9,2)))/I20 -> 2.4571894
B22: buy_t | C22: =C18*'A2 Inputs'!$C$13*(1+'A2 Inputs'!$C$14)^0 -> 4500000 | D22: =D18*'A2 Inputs'!$C$13*(1+'A2 Inputs'!$C$14)^1 -> 5793750 | E22: =E18*'A2 Inputs'!$C$13*(1+'A2 Inputs'!$C$14)^2 -> 7459453.1 | F22: =F18*'A2 Inputs'!$C$13*(1+'A2 Inputs'!$C$14)^3 -> 9604045.9 | G22: =G18*'A2 Inputs'!$C$13*(1+'A2 Inputs'!$C$14)^4 -> 12365209 | H22: =H18*'A2 Inputs'!$C$13*(1+'A2 Inputs'!$C$14)^5 -> 15920207 | I22: =I18*'A2 Inputs'!$C$13*(1+'A2 Inputs'!$C$14)^6 -> 20497266
B23: build_t | C23: =C18*C21+'A2 Inputs'!$C$17*'A2 Inputs'!$C$23+'A2 Inputs'!$C$17 -> 41600000 | D23: =D18*D21+'A2 Inputs'!$C$17*'A2 Inputs'!$C$23 -> 6743739.1 | E23: =E18*E21+'A2 Inputs'!$C$17*'A2 Inputs'!$C$23 -> 7125132.6 | F23: =F18*F21+'A2 Inputs'!$C$17*'A2 Inputs'!$C$23 -> 7654050.2 | G23: =G18*G21+'A2 Inputs'!$C$17*'A2 Inputs'!$C$23 -> 8679785 | H23: =H18*H21+'A2 Inputs'!$C$17*'A2 Inputs'!$C$23 -> 9938822.7 | I23: =I18*I21+'A2 Inputs'!$C$17*'A2 Inputs'!$C$23 -> 11473434
B24: disc_t | C24: =(C22-C23)/(1+'A2 Inputs'!$C$10)^1 -> -33125000 | D24: =(D22-D23)/(1+'A2 Inputs'!$C$10)^2 -> -757325.5 | E24: =(E22-E23)/(1+'A2 Inputs'!$C$10)^3 -> 237962.77 | F24: =(F22-F23)/(1+'A2 Inputs'!$C$10)^4 -> 1239257.5 | G24: =(G22-G23)/(1+'A2 Inputs'!$C$10)^5 -> 2091208.6 | H24: =(H22-H23)/(1+'A2 Inputs'!$C$10)^6 -> 3030355.3 | I24: =(I22-I23)/(1+'A2 Inputs'!$C$10)^7 -> 4081923.5
B26: LR 0.9 / V1 2,000,000 | C26: Y1 | D26: Y2 | E26: Y3 | F26: Y4 | G26: Y5 | H26: Y6 | I26: Y7
B27: vol_t | C27: =2000000*(1+'A2 Inputs'!$C$8)^0 -> 2000000 | D27: =2000000*(1+'A2 Inputs'!$C$8)^1 -> 2500000 | E27: =2000000*(1+'A2 Inputs'!$C$8)^2 -> 3125000 | F27: =2000000*(1+'A2 Inputs'!$C$8)^3 -> 3906250 | G27: =2000000*(1+'A2 Inputs'!$C$8)^4 -> 4882812.5 | H27: =2000000*(1+'A2 Inputs'!$C$8)^5 -> 6103515.6 | I27: =2000000*(1+'A2 Inputs'!$C$8)^6 -> 7629394.5
B28: cumvol_t | C28: =2000000*((1+'A2 Inputs'!$C$8)^1-1)/'A2 Inputs'!$C$8 -> 2000000 | D28: =2000000*((1+'A2 Inputs'!$C$8)^2-1)/'A2 Inputs'!$C$8 -> 4500000 | E28: =2000000*((1+'A2 Inputs'!$C$8)^3-1)/'A2 Inputs'!$C$8 -> 7625000 | F28: =2000000*((1+'A2 Inputs'!$C$8)^4-1)/'A2 Inputs'!$C$8 -> 11531250 | G28: =2000000*((1+'A2 Inputs'!$C$8)^5-1)/'A2 Inputs'!$C$8 -> 16414062 | H28: =2000000*((1+'A2 Inputs'!$C$8)^6-1)/'A2 Inputs'!$C$8 -> 22517578 | I28: =2000000*((1+'A2 Inputs'!$C$8)^7-1)/'A2 Inputs'!$C$8 -> 30146973
B29: yield_t | C29: ='A2 Inputs'!$C$21+('A2 Inputs'!$C$22-'A2 Inputs'!$C$21)*MIN(1,(0)/3) -> 0.8 | D29: ='A2 Inputs'!$C$21+('A2 Inputs'!$C$22-'A2 Inputs'!$C$21)*MIN(1,(1)/3) -> 0.85666667 | E29: ='A2 Inputs'!$C$21+('A2 Inputs'!$C$22-'A2 Inputs'!$C$21)*MIN(1,(2)/3) -> 0.91333333 | F29: ='A2 Inputs'!$C$21+('A2 Inputs'!$C$22-'A2 Inputs'!$C$21)*MIN(1,(3)/3) -> 0.97 | G29: ='A2 Inputs'!$C$21+('A2 Inputs'!$C$22-'A2 Inputs'!$C$21)*MIN(1,(4)/3) -> 0.97 | H29: ='A2 Inputs'!$C$21+('A2 Inputs'!$C$22-'A2 Inputs'!$C$21)*MIN(1,(5)/3) -> 0.97 | I29: ='A2 Inputs'!$C$21+('A2 Inputs'!$C$22-'A2 Inputs'!$C$21)*MIN(1,(6)/3) -> 0.97
B30: inhouse_t | C30: ='A2 Inputs'!$C$19*((C28/2000000)^(LOG(0.9,2)))/C29 -> 4.5 | D30: ='A2 Inputs'!$C$19*((D28/2000000)^(LOG(0.9,2)))/D29 -> 3.7149913 | E30: ='A2 Inputs'!$C$19*((E28/2000000)^(LOG(0.9,2)))/E29 -> 3.2160848 | F30: ='A2 Inputs'!$C$19*((F28/2000000)^(LOG(0.9,2)))/F29 -> 2.8436737 | G30: ='A2 Inputs'!$C$19*((G28/2000000)^(LOG(0.9,2)))/G29 -> 2.69508 | H30: ='A2 Inputs'!$C$19*((H28/2000000)^(LOG(0.9,2)))/H29 -> 2.5686254 | I30: ='A2 Inputs'!$C$19*((I28/2000000)^(LOG(0.9,2)))/I29 -> 2.4571894
B31: buy_t | C31: =C27*'A2 Inputs'!$C$13*(1+'A2 Inputs'!$C$14)^0 -> 9000000 | D31: =D27*'A2 Inputs'!$C$13*(1+'A2 Inputs'!$C$14)^1 -> 11587500 | E31: =E27*'A2 Inputs'!$C$13*(1+'A2 Inputs'!$C$14)^2 -> 14918906 | F31: =F27*'A2 Inputs'!$C$13*(1+'A2 Inputs'!$C$14)^3 -> 19208092 | G31: =G27*'A2 Inputs'!$C$13*(1+'A2 Inputs'!$C$14)^4 -> 24730418 | H31: =H27*'A2 Inputs'!$C$13*(1+'A2 Inputs'!$C$14)^5 -> 31840413 | I31: =I27*'A2 Inputs'!$C$13*(1+'A2 Inputs'!$C$14)^6 -> 40994532
B32: build_t | C32: =C27*C30+'A2 Inputs'!$C$17*'A2 Inputs'!$C$23+'A2 Inputs'!$C$17 -> 46100000 | D32: =D27*D30+'A2 Inputs'!$C$17*'A2 Inputs'!$C$23 -> 11387478 | E32: =E27*E30+'A2 Inputs'!$C$17*'A2 Inputs'!$C$23 -> 12150265 | F32: =F27*F30+'A2 Inputs'!$C$17*'A2 Inputs'!$C$23 -> 13208100 | G32: =G27*G30+'A2 Inputs'!$C$17*'A2 Inputs'!$C$23 -> 15259570 | H32: =H27*H30+'A2 Inputs'!$C$17*'A2 Inputs'!$C$23 -> 17777645 | I32: =I27*I30+'A2 Inputs'!$C$17*'A2 Inputs'!$C$23 -> 20846868
B33: disc_t | C33: =(C31-C32)/(1+'A2 Inputs'!$C$10)^1 -> -33125000 | D33: =(D31-D32)/(1+'A2 Inputs'!$C$10)^2 -> 159456.13 | E33: =(E31-E32)/(1+'A2 Inputs'!$C$10)^3 -> 1970664.1 | F33: =(F31-F32)/(1+'A2 Inputs'!$C$10)^4 -> 3813103 | G33: =(G31-G32)/(1+'A2 Inputs'!$C$10)^5 -> 5374013.6 | H33: =(H31-H32)/(1+'A2 Inputs'!$C$10)^6 -> 7124635.9 | I33: =(I31-I32)/(1+'A2 Inputs'!$C$10)^7 -> 9113780.3
B35: LR 0.9 / V1 3,500,000 | C35: Y1 | D35: Y2 | E35: Y3 | F35: Y4 | G35: Y5 | H35: Y6 | I35: Y7
B36: vol_t | C36: =3500000*(1+'A2 Inputs'!$C$8)^0 -> 3500000 | D36: =3500000*(1+'A2 Inputs'!$C$8)^1 -> 4375000 | E36: =3500000*(1+'A2 Inputs'!$C$8)^2 -> 5468750 | F36: =3500000*(1+'A2 Inputs'!$C$8)^3 -> 6835937.5 | G36: =3500000*(1+'A2 Inputs'!$C$8)^4 -> 8544921.9 | H36: =3500000*(1+'A2 Inputs'!$C$8)^5 -> 10681152 | I36: =3500000*(1+'A2 Inputs'!$C$8)^6 -> 13351440
B37: cumvol_t | C37: =3500000*((1+'A2 Inputs'!$C$8)^1-1)/'A2 Inputs'!$C$8 -> 3500000 | D37: =3500000*((1+'A2 Inputs'!$C$8)^2-1)/'A2 Inputs'!$C$8 -> 7875000 | E37: =3500000*((1+'A2 Inputs'!$C$8)^3-1)/'A2 Inputs'!$C$8 -> 13343750 | F37: =3500000*((1+'A2 Inputs'!$C$8)^4-1)/'A2 Inputs'!$C$8 -> 20179688 | G37: =3500000*((1+'A2 Inputs'!$C$8)^5-1)/'A2 Inputs'!$C$8 -> 28724609 | H37: =3500000*((1+'A2 Inputs'!$C$8)^6-1)/'A2 Inputs'!$C$8 -> 39405762 | I37: =3500000*((1+'A2 Inputs'!$C$8)^7-1)/'A2 Inputs'!$C$8 -> 52757202
